<?xml version="1.0" encoding="UTF-8"?>
<testsuite errors="0" failures="0" file="rest_utils/tests/test_authentication.py" name="rest_utils.tests.test_authentication.TestAuthenticationWithExpiredPassword-20220725105046" skipped="0" tests="3" time="0.902" timestamp="2022-07-25T11:08:17">
	<testcase classname="rest_utils.tests.test_authentication.TestAuthenticationWithExpiredPassword" file="rest_utils/tests/test_authentication.py" line="1316" name="test_customer_auth_with_expired_password" time="0.418" timestamp="2022-07-25T11:08:16">
		<system-out>
<![CDATA[]]>		</system-out>
		<system-err>
<![CDATA[]]>		</system-err>
	</testcase>
	<testcase classname="rest_utils.tests.test_authentication.TestAuthenticationWithExpiredPassword" file="rest_utils/tests/test_authentication.py" line="1347" name="test_customer_auth_with_unexpired_password" time="0.357" timestamp="2022-07-25T11:08:17">
		<system-out>
<![CDATA[]]>		</system-out>
		<system-err>
<![CDATA[]]>		</system-err>
	</testcase>
	<testcase classname="rest_utils.tests.test_authentication.TestAuthenticationWithExpiredPassword" file="rest_utils/tests/test_authentication.py" line="1302" name="test_invalid_user_auth" time="0.127" timestamp="2022-07-25T11:08:17">
		<system-out>
<![CDATA[]]>		</system-out>
		<system-err>
<![CDATA[]]>		</system-err>
	</testcase>
</testsuite>
